<?xml version="1.0"?>
<robot xmlns:xacro="http://www.ros.org/wiki/xacro" name="diff_bot">
    <xacro:property name="base_width" value="0.3"/>
    <xacro:property name="base_length" value="0.4" />
    <xacro:property name="base_height" value="0.04" />
    <xacro:property name="wheel_radius" value="0.07" />
    <xacro:property name="drive_wheel_offset" value="0.08" />
    <xacro:property name="caster_wheel_radius" value="0.05" />
    <xacro:property name="caster_wheel_offset" value="0.1" />

    <xacro:macro name="box_inertia" params="m w h d">
        <inertial>
            <mass value="${m}" />
            <inertia ixy="0" ixz="0" iyz="0" ixx="${m / 12 * (h*h + d*d)}" iyy="${m / 12 * (w*w + d*d)}" izz="${m / 12 * (w*w + h*h)}" />
        </inertial>
    </xacro:macro>

    <xacro:macro name="cylinder_inertia" params="m r h">
        <inertial>
            <mass value="${m}" />
            <inertia ixy="0" ixz="0" iyz="0" ixx="${m / 12 * (3*r*r + h*h)}" iyy="${m / 12 * (3*r*r + h*h)}" izz="${m / 2 * r*r}" />
        </inertial>
    </xacro:macro>

    <xacro:macro name="sphere_inertia" params="m r">
        <inertial>
            <mass value="${m}" />
            <inertia ixy="0" ixz="0" iyz="0" ixx="${m * 2 / 5 * r*r}" iyy="${m * 2 / 5 * r*r}" izz="${m * 2 / 5 * r*r}" />
        </inertial>
    </xacro:macro>

    <xacro:macro name="wheel" params="prefix side">
        <link name="${prefix}_wheel">
            <visual>
                <origin xyz="0 0 0" rpy="${pi/2} 0 0" />
                <geometry>
                    <cylinder radius="${wheel_radius}" length="0.01" />
                </geometry>
            </visual>
            <collision>
                <origin xyz="0 0 0" rpy="${pi/2} 0 0" />
                <geometry>
                    <cylinder radius="${wheel_radius}" length="0.01" />
                </geometry>
            </collision>
            <xacro:cylinder_inertia m="10" r="${wheel_radius}" h="0.01" />
        </link>

        <joint name="${prefix}_wheel_joint" type="continuous">
            <axis xyz="0 1 0" rpy="0 0 0" />
            <parent link="base_link" />
            <child link="${prefix}_wheel" />
            <origin xyz="${drive_wheel_offset} ${(base_width / 2 * side)} 0" rpy="0 0 0" />
        </joint>
    </xacro:macro>

    <material name="blue">
        <color rgba="0 0 0.8 1" />
    </material>

    <link name="base_link">
        <xacro:box_inertia m="10" w="${base_width}" h="${base_height}" d="${base_length}" />
        <visual>
            <origin xyz="0 0 0" rpy="0 0 0" />
            <geometry>
                <box size="${base_length} ${base_width} ${base_height}" />
            </geometry>
            <material name="blue" />
        </visual>
        <collision>
            <origin xyz="0 0 0" rpy="0 0 0" />
            <geometry>
                <box size="${base_length} ${base_width} ${base_height}" />
            </geometry>
        </collision>
    </link>

    <xacro:wheel prefix="right" side="-1" />
    <xacro:wheel prefix="left" side="1" />

    <link name="caster_wheel">
        <visual>
            <origin xyz="0 0 0" rpy="0 0 0" />
            <geometry>
                <sphere radius="${caster_wheel_radius}" />
            </geometry>
        </visual>
        <collision>
            <origin xyz="0 0 0" rpy="0 0 0" />
            <geometry>
                <sphere radius="${caster_wheel_radius}" />
            </geometry>
        </collision>
        <xacro:sphere_inertia m="5" r="${caster_wheel_radius}" />
    </link>

    <joint name="caster_wheel_joint" type="continuous">
        <axis xyz="0 1 0" rpy="0 0 0" />
        <parent link="base_link" />
        <child link="caster_wheel" />
        <origin xyz="-${caster_wheel_offset} 0 -${base_height / 2}" rpy="0 0 0" />
    </joint>
</robot>