<?xml version="1.0"?>
<robot xmlns:xacro="http://www.ros.org/wiki/xacro" name="diff_bot">
    <xacro:include filename="properties.xacro" />
    <xacro:include filename="macros.xacro" />
    <xacro:include filename="gazebo_elements.xacro" />
    <xacro:include filename="sensors.xacro" />

    <material name="blue">
        <color rgba="0 0 0.8 1" />
    </material>

    <link name="base_footprint" />

    <link name="base_link">
        <xacro:box_inertia m="5.0" w="${base_width}" h="${base_height}" d="${base_length}" />
        <visual>
            <origin xyz="0 0 0" rpy="0 0 0" />
            <geometry>
                <box size="${base_length} ${base_width} ${base_height}" />
            </geometry>
            <material name="blue" />
        </visual>
        <collision>
            <origin xyz="0 0 0" rpy="0 0 0" />
            <geometry>
                <box size="${base_length} ${base_width} ${base_height}" />
            </geometry>
        </collision>
    </link>

    <xacro:wheel prefix="right" side="-1" />
    <xacro:wheel prefix="left" side="1" />

    <link name="caster_wheel">
        <visual>
            <origin xyz="0 0 0" rpy="0 0 0" />
            <geometry>
                <sphere radius="${caster_wheel_radius}" />
            </geometry>
        </visual>
        <collision>
            <origin xyz="0 0 0" rpy="0 0 0" />
            <geometry>
                <sphere radius="${caster_wheel_radius}" />
            </geometry>
        </collision>
        <xacro:sphere_inertia m="1.5" r="${caster_wheel_radius}" />
    </link>

    <joint name="caster_wheel_joint" type="continuous">
        <axis xyz="0 1 0" rpy="0 0 0" />
        <parent link="base_link" />
        <child link="caster_wheel" />
        <origin xyz="-${caster_wheel_offset} 0.0 -${base_height / 2.0}" rpy="0 0 0" />
    </joint>

    <joint name="root_joint" type="fixed">
        <parent link="base_footprint" />
        <child link="base_link" />
        <origin xyz="0 0 0" rpy="0 0 0" />
    </joint>
</robot>